<?xml version="1.0" ?>
<!-- =================================================================================== -->
<!-- |    This document was autogenerated by xacro from crazyflie2.xacro               | -->
<!-- |    EDITING THIS FILE BY HAND IS NOT RECOMMENDED                                 | -->
<!-- =================================================================================== -->
<!--
  Copyright 2018 Giuseppe Silano, University of Sannio in Benevento, Italy
  Copyright 2018 Emanuele Aucone, University of Sannio in Benevento, Italy
  Copyright 2018 Benjamin Rodriguez, MIT, USA
  Copyright 2018 Luigi Iannelli, University of Sannio in Benevento, Italy

  Licensed under the Apache License, Version 2.0 (the "License");
  you may not use this file except in compliance with the License.
  You may obtain a copy of the License at

  http://www.apache.org/licenses/LICENSE-2.0

  Unless required by applicable law or agreed to in writing, software
  distributed under the License is distributed on an "AS IS" BASIS,
  WITHOUT WARRANTIES OR CONDITIONS OF ANY KIND, either express or implied.
  See the License for the specific language governing permissions and
  limitations under the License.
-->
<robot name="crazyflie2" xmlns:xacro="http://ros.org/wiki/xacro">
  <link name="crazyflie2/base_link"/>
  <joint name="crazyflie2/base_joint" type="fixed">
    <origin rpy="0 0 0" xyz="0 0 0"/>
    <parent link="crazyflie2/base_link"/>
    <child link="crazyflie2/base_link_inertia"/>
  </joint>
  <link name="crazyflie2/base_link_inertia">
    <inertial>
      <mass value="0.025"/>
      <!-- [kg] -->
      <origin xyz="0 0 0"/>
      <inertia ixx="1.657171e-05" ixy="0.0" ixz="0.0" iyy="1.657171e-05" iyz="0.0" izz="2.9261652e-05"/>
    </inertial>
    <visual>
      <origin rpy="0 0 0" xyz="0 0 0"/>
      <geometry>
        <mesh filename="package://rotors_description/meshes/crazyflie2.dae" scale="1 1 1"/>
      </geometry>
    </visual>
    <collision>
      <origin rpy="0 0 0" xyz="0 0 0"/>
      <geometry>
        <box size="0.045 0.045 0.03"/>
        <!-- [m] [m] [m] -->
      </geometry>
    </collision>
  </link>
  <!-- attach multirotor_base_plugin to the base_link -->
  <gazebo>
    <plugin filename="librotors_gazebo_multirotor_base_plugin.so" name="multirotor_base_plugin">
      <robotNamespace>crazyflie2</robotNamespace>
      <linkName>crazyflie2/base_link</linkName>
      <rotorVelocitySlowdownSim>50</rotorVelocitySlowdownSim>
    </plugin>
  </gazebo>
  <joint name="crazyflie2/rotor_0_joint" type="continuous">
    <origin rpy="0 0 0" xyz="0.0325269119346 -0.0325269119346 0.024"/>
    <axis xyz="0 0 1"/>
    <!-- TODO(ff): not currently set because it's not yet supported -->
    <!-- <limit effort="2000" velocity="${max_rot_velocity}" /> -->
    <parent link="crazyflie2/base_link"/>
    <child link="crazyflie2/rotor_0"/>
  </joint>
  <link name="crazyflie2/rotor_0">
    <inertial>
      <mass value="0.0005"/>
      <!-- [kg] -->
      <inertia ixx="1.20833285e-07" ixy="0.0" ixz="0.0" iyy="1.07343707062e-06" iyz="0.0" izz="1.15677037062e-06"/>
    </inertial>
    <visual>
      <geometry>
        <mesh filename="package://rotors_description/meshes/propeller_ccw.dae" scale="0.0225 0.0225 0.0225"/>
        <!-- The propeller meshes have a radius of 1m -->
        <!-- <box size="${2*radius_rotor} 0.01 0.005"/> -->
      </geometry>
    </visual>
    <collision>
      <geometry>
        <cylinder length="0.005" radius="0.0225"/>
        <!-- [m] -->
      </geometry>
    </collision>
  </link>
  <gazebo>
    <plugin filename="librotors_gazebo_motor_model.so" name="crazyflie2_front-right_motor_model">
      <robotNamespace>crazyflie2</robotNamespace>
      <jointName>crazyflie2/rotor_0_joint</jointName>
      <linkName>crazyflie2/rotor_0</linkName>
      <turningDirection>ccw</turningDirection>
      <timeConstantUp>0.0125</timeConstantUp>
      <timeConstantDown>0.025</timeConstantDown>
      <maxRotVelocity>2618</maxRotVelocity>
      <motorConstant>1.28192e-08</motorConstant>
      <momentConstant>0.005964552</momentConstant>
      <commandSubTopic>gazebo/command/motor_speed</commandSubTopic>
      <motorNumber>0</motorNumber>
      <rotorDragCoefficient>8.06428e-05</rotorDragCoefficient>
      <rollingMomentCoefficient>1e-06</rollingMomentCoefficient>
      <motorSpeedPubTopic>motor_speed/0</motorSpeedPubTopic>
      <rotorVelocitySlowdownSim>50</rotorVelocitySlowdownSim>
    </plugin>
  </gazebo>
  <gazebo reference="crazyflie2/rotor_0">
    <material>Gazebo/Red</material>
  </gazebo>
  <joint name="crazyflie2/rotor_1_joint" type="continuous">
    <origin rpy="0 0 0" xyz="-0.0325269119346 -0.0325269119346 0.024"/>
    <axis xyz="0 0 1"/>
    <!-- TODO(ff): not currently set because it's not yet supported -->
    <!-- <limit effort="2000" velocity="${max_rot_velocity}" /> -->
    <parent link="crazyflie2/base_link"/>
    <child link="crazyflie2/rotor_1"/>
  </joint>
  <link name="crazyflie2/rotor_1">
    <inertial>
      <mass value="0.0005"/>
      <!-- [kg] -->
      <inertia ixx="1.20833285e-07" ixy="0.0" ixz="0.0" iyy="1.07343707062e-06" iyz="0.0" izz="1.15677037062e-06"/>
    </inertial>
    <visual>
      <geometry>
        <mesh filename="package://rotors_description/meshes/propeller_cw.dae" scale="0.0225 0.0225 0.0225"/>
        <!-- The propeller meshes have a radius of 1m -->
        <!-- <box size="${2*radius_rotor} 0.01 0.005"/> -->
      </geometry>
    </visual>
    <collision>
      <geometry>
        <cylinder length="0.005" radius="0.0225"/>
        <!-- [m] -->
      </geometry>
    </collision>
  </link>
  <gazebo>
    <plugin filename="librotors_gazebo_motor_model.so" name="crazyflie2_back-right_motor_model">
      <robotNamespace>crazyflie2</robotNamespace>
      <jointName>crazyflie2/rotor_1_joint</jointName>
      <linkName>crazyflie2/rotor_1</linkName>
      <turningDirection>cw</turningDirection>
      <timeConstantUp>0.0125</timeConstantUp>
      <timeConstantDown>0.025</timeConstantDown>
      <maxRotVelocity>2618</maxRotVelocity>
      <motorConstant>1.28192e-08</motorConstant>
      <momentConstant>0.005964552</momentConstant>
      <commandSubTopic>gazebo/command/motor_speed</commandSubTopic>
      <motorNumber>1</motorNumber>
      <rotorDragCoefficient>8.06428e-05</rotorDragCoefficient>
      <rollingMomentCoefficient>1e-06</rollingMomentCoefficient>
      <motorSpeedPubTopic>motor_speed/1</motorSpeedPubTopic>
      <rotorVelocitySlowdownSim>50</rotorVelocitySlowdownSim>
    </plugin>
  </gazebo>
  <gazebo reference="crazyflie2/rotor_1">
    <material>Gazebo/Blue</material>
  </gazebo>
  <joint name="crazyflie2/rotor_2_joint" type="continuous">
    <origin rpy="0 0 0" xyz="-0.0325269119346 0.0325269119346 0.024"/>
    <axis xyz="0 0 1"/>
    <!-- TODO(ff): not currently set because it's not yet supported -->
    <!-- <limit effort="2000" velocity="${max_rot_velocity}" /> -->
    <parent link="crazyflie2/base_link"/>
    <child link="crazyflie2/rotor_2"/>
  </joint>
  <link name="crazyflie2/rotor_2">
    <inertial>
      <mass value="0.0005"/>
      <!-- [kg] -->
      <inertia ixx="1.20833285e-07" ixy="0.0" ixz="0.0" iyy="1.07343707062e-06" iyz="0.0" izz="1.15677037062e-06"/>
    </inertial>
    <visual>
      <geometry>
        <mesh filename="package://rotors_description/meshes/propeller_ccw.dae" scale="0.0225 0.0225 0.0225"/>
        <!-- The propeller meshes have a radius of 1m -->
        <!-- <box size="${2*radius_rotor} 0.01 0.005"/> -->
      </geometry>
    </visual>
    <collision>
      <geometry>
        <cylinder length="0.005" radius="0.0225"/>
        <!-- [m] -->
      </geometry>
    </collision>
  </link>
  <gazebo>
    <plugin filename="librotors_gazebo_motor_model.so" name="crazyflie2_back-left_motor_model">
      <robotNamespace>crazyflie2</robotNamespace>
      <jointName>crazyflie2/rotor_2_joint</jointName>
      <linkName>crazyflie2/rotor_2</linkName>
      <turningDirection>ccw</turningDirection>
      <timeConstantUp>0.0125</timeConstantUp>
      <timeConstantDown>0.025</timeConstantDown>
      <maxRotVelocity>2618</maxRotVelocity>
      <motorConstant>1.28192e-08</motorConstant>
      <momentConstant>0.005964552</momentConstant>
      <commandSubTopic>gazebo/command/motor_speed</commandSubTopic>
      <motorNumber>2</motorNumber>
      <rotorDragCoefficient>8.06428e-05</rotorDragCoefficient>
      <rollingMomentCoefficient>1e-06</rollingMomentCoefficient>
      <motorSpeedPubTopic>motor_speed/2</motorSpeedPubTopic>
      <rotorVelocitySlowdownSim>50</rotorVelocitySlowdownSim>
    </plugin>
  </gazebo>
  <gazebo reference="crazyflie2/rotor_2">
    <material>Gazebo/Blue</material>
  </gazebo>
  <joint name="crazyflie2/rotor_3_joint" type="continuous">
    <origin rpy="0 0 0" xyz="0.0325269119346 0.0325269119346 0.024"/>
    <axis xyz="0 0 1"/>
    <!-- TODO(ff): not currently set because it's not yet supported -->
    <!-- <limit effort="2000" velocity="${max_rot_velocity}" /> -->
    <parent link="crazyflie2/base_link"/>
    <child link="crazyflie2/rotor_3"/>
  </joint>
  <link name="crazyflie2/rotor_3">
    <inertial>
      <mass value="0.0005"/>
      <!-- [kg] -->
      <inertia ixx="1.20833285e-07" ixy="0.0" ixz="0.0" iyy="1.07343707062e-06" iyz="0.0" izz="1.15677037062e-06"/>
    </inertial>
    <visual>
      <geometry>
        <mesh filename="package://rotors_description/meshes/propeller_cw.dae" scale="0.0225 0.0225 0.0225"/>
        <!-- The propeller meshes have a radius of 1m -->
        <!-- <box size="${2*radius_rotor} 0.01 0.005"/> -->
      </geometry>
    </visual>
    <collision>
      <geometry>
        <cylinder length="0.005" radius="0.0225"/>
        <!-- [m] -->
      </geometry>
    </collision>
  </link>
  <gazebo>
    <plugin filename="librotors_gazebo_motor_model.so" name="crazyflie2_front-left_motor_model">
      <robotNamespace>crazyflie2</robotNamespace>
      <jointName>crazyflie2/rotor_3_joint</jointName>
      <linkName>crazyflie2/rotor_3</linkName>
      <turningDirection>cw</turningDirection>
      <timeConstantUp>0.0125</timeConstantUp>
      <timeConstantDown>0.025</timeConstantDown>
      <maxRotVelocity>2618</maxRotVelocity>
      <motorConstant>1.28192e-08</motorConstant>
      <momentConstant>0.005964552</momentConstant>
      <commandSubTopic>gazebo/command/motor_speed</commandSubTopic>
      <motorNumber>3</motorNumber>
      <rotorDragCoefficient>8.06428e-05</rotorDragCoefficient>
      <rollingMomentCoefficient>1e-06</rollingMomentCoefficient>
      <motorSpeedPubTopic>motor_speed/3</motorSpeedPubTopic>
      <rotorVelocitySlowdownSim>50</rotorVelocitySlowdownSim>
    </plugin>
  </gazebo>
  <gazebo reference="crazyflie2/rotor_3">
    <material>Gazebo/Green</material>
  </gazebo>


  <!-- whycon marker -->
  <joint name="crazyflie2/whycon_marker_joint" type="fixed">
    <origin rpy="0 0 0" xyz="0 0 0.3"/>
    <axis xyz="0 0 1"/>
    <!-- TODO(ff): not currently set because it's not yet supported -->
    <!-- <limit effort="2000" velocity="${max_rot_velocity}" /> -->
    <parent link="crazyflie2/base_link"/>
    <child link="crazyflie2/whycon_marker"/>
  </joint>
  <link name="crazyflie2/whycon_marker">
    <inertial>
      <mass value="0.005"/>
      <!-- [kg] -->
      <inertia ixx="0.00000801" ixy="0.0" ixz="0.0"
        iyy="0.00000801" iyz="0.0"
        izz="0.000016"/>
      <!-- <inertia ixx="1.6e-05" ixy="0.0" ixz="0.0" iyy="1.6e-05" iyz="0.0" izz="1.6e-05"/> -->
    </inertial>
    <visual>
      <geometry>
        <mesh filename="package://rotors_description/meshes/whycon_maker_base.stl"/>
        <!-- The propeller meshes have a radius of 1m -->
        <!-- <box size="${2*radius_rotor} 0.01 0.005"/> -->
      </geometry>
    </visual>
    <collision>
      <geometry>
        <cylinder length="0.005" radius="0.0225"/>
        <!-- [m] -->
      </geometry>
    </collision>
  </link> 
</robot>

